Workbook

Sheet 1_Summary Dashboard
A1: OPPORTUNITY ZONE FUND PRO FORMA
A2: Multifamily Development Analysis
A4: PROJECT OVERVIEW | F4: KEY METRICS
A5: Project Name: | B5: OZ Multifamily Fund - Property 1 | F5: Total Project Cost: | G5: ='2_Development Budget'!C32
A6: Location: | B6: Enter City, State | F6: Equity Required: | G6: ='5_Debt Schedule'!C7
A7: Property Type: | B7: Multifamily | F7: Debt Amount: | G7: ='5_Debt Schedule'!C5
A8: Total Units: | B8: 50 | F8: LTV %: | G8: ='5_Debt Schedule'!C4
A9: Year Built/Renovated: | B9: 2026 | F9: Cap Rate (Going-In): | G9: ='4_Operating Expenses'!D18/'2_Development Budget'!C32
A10: OZ Designation: | B10: Qualified Opportunity Zone | F10: Price Per Unit: | G10: ='2_Development Budget'!C32/B8
A12: RETURNS SNAPSHOT
A13: Year 1 Cash-on-Cash: | B13: ='6_Cash Flow Analysis'!C24 | F13: Total Cash Returned: | G13: ='6_Cash Flow Analysis'!L25
A14: 10-Year IRR: | B14: ='7_Returns Exit'!C30 | F14: Exit Equity Proceeds: | G14: ='7_Returns Exit'!C13
A15: Equity Multiple: | B15: ='7_Returns Exit'!C29 | F15: Total Return ($): | G15: ='7_Returns Exit'!C27
A16: Exit Value (Year 10): | B16: ='7_Returns Exit'!C9 | F16: Total Return (%): | G16: ='7_Returns Exit'!C28
A18: INVESTMENT TIMELINE
A19: Year 0 | B19: Years 1-2 | C19: Years 3-5 | D19: Years 6-9 | E19: Year 10
A20: Acquisition & Development | B20: Renovation & Lease-Up | C20: Stabilization & Refinance | D20: Cash Flow Operations | E20: Tax-Free Exit
A22: OZ TAX BENEFITS
A23: Original Capital Gain (Input): | B23: 1000000 | F23: Traditional Investment Tax: | G23: ='7_Returns Exit'!C35
A24: Federal Tax Rate: | B24: 0.238 | F24: OZ Fund Tax: | G24: ='7_Returns Exit'!C39
A25: State Tax Rate: | B25: 0.05 | F25: Tax Savings from OZ: | G25: ='7_Returns Exit'!C42
A26: Tax Deferred (to Dec 2026): | B26: =B23*(B24+B25)
A27: Tax-Free Appreciation: | B27: ='7_Returns Exit'!C27

Sheet 2_Development Budget
A1: DEVELOPMENT BUDGET
A3: Category | B3: Description | C3: Amount | D3: % of Total
A4: LAND ACQUISITION
B5: Land Purchase Price | C5: 3000000 | D5: =C5/$C$32
B6: Closing Costs (2%) | C6: =C5*0.02 | D6: =C6/$C$32
B7: Due Diligence | C7: 25000 | D7: =C7/$C$32
B8: Subtotal Land | C8: =SUM(C5:C7) | D8: =C8/$C$32
A9: HARD CONSTRUCTION COSTS
B10: Site Work & Utilities | C10: 500000 | D10: =C10/$C$32
B11: Building Construction | C11: 8500000 | D11: =C11/$C$32
B12: Parking & Landscaping | C12: 400000 | D12: =C12/$C$32
B13: FF&E (Common Areas) | C13: 300000 | D13: =C13/$C$32
B14: Unit Finishes/Upgrades | C14: 300000 | D14: =C14/$C$32
B15: Subtotal Hard Costs | C15: =SUM(C10:C14) | D15: =C15/$C$32
A16: SOFT COSTS
B17: Architecture & Design | C17: 350000 | D17: =C17/$C$32
B18: Engineering | C18: 150000 | D18: =C18/$C$32
B19: Permits & Impact Fees | C19: 200000 | D19: =C19/$C$32
B20: Legal & Accounting | C20: 100000 | D20: =C20/$C$32
B21: Financing Fees (2% of loan) | C21: =$C$32*0.75*0.02 | D21: =C21/$C$32
B22: Construction Interest | C22: 250000 | D22: =C22/$C$32
B23: Insurance (Builder's Risk) | C23: 75000 | D23: =C23/$C$32
B24: Marketing & Lease-Up | C24: 100000 | D24: =C24/$C$32
B25: Subtotal Soft Costs | C25: =SUM(C17:C24) | D25: =C25/$C$32
A26: DEVELOPMENT FEE
B27: Development Fee (5% of hard costs) | C27: =C15*0.05 | D27: =C27/$C$32
A28: CONTINGENCY
B29: Contingency (7% of hard + soft) | C29: =(C15+C25)*0.07 | D29: =C29/$C$32
A31: TOTAL PROJECT COST | C31: =C8+C15+C25+C27+C29 | D31: 100.0%
A33: Cost Per Unit: | C33: =C31/'1_Summary Dashboard'!B8
A34: Hard Cost Per Unit: | C34: =C15/'1_Summary Dashboard'!B8

Sheet 3_Unit Mix Revenue
A1: UNIT MIX & REVENUE PROJECTIONS
A3: Unit Type | B3: Units | C3: Mo. Rent | D3: Growth | E3: Year 1 | F3: Year 2 | G3: Year 3 | H3: Year 4 | I3: Year 5 | J3: Year 6 | K3: Year 7 | L3: Year 8 | M3: Year 9 | N3: Year 10
A4: RENTAL INCOME
A5: Studio | B5: 10 | C5: 1200 | D5: 0.03 | E5: =B5*C5*12 | F5: =E5*(1+$D5) | G5: =F5*(1+$D5) | H5: =G5*(1+$D5) | I5: =H5*(1+$D5) | J5: =I5*(1+$D5) | K5: =J5*(1+$D5) | L5: =K5*(1+$D5) | M5: =L5*(1+$D5) | N5: =M5*(1+$D5)
A6: 1 Bedroom | B6: 25 | C6: 1500 | D6: 0.03 | E6: =B6*C6*12 | F6: =E6*(1+$D6) | G6: =F6*(1+$D6) | H6: =G6*(1+$D6) | I6: =H6*(1+$D6) | J6: =I6*(1+$D6) | K6: =J6*(1+$D6) | L6: =K6*(1+$D6) | M6: =L6*(1+$D6) | N6: =M6*(1+$D6)
A7: 2 Bedroom | B7: 12 | C7: 2000 | D7: 0.03 | E7: =B7*C7*12 | F7: =E7*(1+$D7) | G7: =F7*(1+$D7) | H7: =G7*(1+$D7) | I7: =H7*(1+$D7) | J7: =I7*(1+$D7) | K7: =J7*(1+$D7) | L7: =K7*(1+$D7) | M7: =L7*(1+$D7) | N7: =M7*(1+$D7)
A8: 3 Bedroom | B8: 3 | C8: 2400 | D8: 0.03 | E8: =B8*C8*12 | F8: =E8*(1+$D8) | G8: =F8*(1+$D8) | H8: =G8*(1+$D8) | I8: =H8*(1+$D8) | J8: =I8*(1+$D8) | K8: =J8*(1+$D8) | L8: =K8*(1+$D8) | M8: =L8*(1+$D8) | N8: =M8*(1+$D8)
A9: Total Units | B9: =SUM(B5:B8)
A10: GROSS POTENTIAL RENT | E10: =SUM(E5:E8) | F10: =SUM(F5:F8) | G10: =SUM(G5:G8) | H10: =SUM(H5:H8) | I10: =SUM(I5:I8) | J10: =SUM(J5:J8) | K10: =SUM(K5:K8) | L10: =SUM(L5:L8) | ... N10: =SUM(N5:N8)
A12: VACANCY & ADJUSTMENTS
A13: Physical Vacancy | B13: 0.05 | E13: =-E$10*$B13 | F13: =-F$10*$B13 | G13: =-G$10*$B13 | H13: =-H$10*$B13 | I13: =-I$10*$B13 | J13: =-J$10*$B13 | K13: =-K$10*$B13 | L13: =-L$10*$B13 | ... N13: =-N$10*$B13
A14: Collection Loss/Bad Debt | B14: 0.005 | E14: =-E$10*$B14 | F14: =-F$10*$B14 | G14: =-G$10*$B14 | H14: =-H$10*$B14 | I14: =-I$10*$B14 | J14: =-J$10*$B14 | K14: =-K$10*$B14 | L14: =-L$10*$B14 | ... N14: =-N$10*$B14
A15: Concessions | B15: 0.005 | E15: =-E$10*$B15 | F15: =-F$10*$B15 | G15: =-G$10*$B15 | H15: =-H$10*$B15 | I15: =-I$10*$B15 | J15: =-J$10*$B15 | K15: =-K$10*$B15 | L15: =-L$10*$B15 | ... N15: =-N$10*$B15
A16: Total Vacancy/Loss | E16: =SUM(E13:E15) | F16: =SUM(F13:F15) | G16: =SUM(G13:G15) | H16: =SUM(H13:H15) | I16: =SUM(I13:I15) | J16: =SUM(J13:J15) | K16: =SUM(K13:K15) | L16: =SUM(L13:L15) | ... N16: =SUM(N13:N15)
A17: GROSS OPERATING INCOME | E17: =E10+E16 | F17: =F10+F16 | G17: =G10+G16 | H17: =H10+H16 | I17: =I10+I16 | J17: =J10+J16 | K17: =K10+K16 | L17: =L10+L16 | ... N17: =N10+N16
A19: OTHER INCOME
A20: Parking | B20: 50 | C20: per unit/mo | D20: 0.03 | E20: =$B$9*$B20*12 | F20: =E20*(1+$D20) | G20: =F20*(1+$D20) | H20: =G20*(1+$D20) | I20: =H20*(1+$D20) | J20: =I20*(1+$D20) | K20: =J20*(1+$D20) | L20: =K20*(1+$D20) | M20: =L20*(1+$D20) | N20: =M20*(1+$D20)
A21: Storage | B21: 25 | C21: per unit/mo | D21: 0.03 | E21: =$B$9*$B21*12 | F21: =E21*(1+$D21) | G21: =F21*(1+$D21) | H21: =G21*(1+$D21) | I21: =H21*(1+$D21) | J21: =I21*(1+$D21) | K21: =J21*(1+$D21) | L21: =K21*(1+$D21) | M21: =L21*(1+$D21) | N21: =M21*(1+$D21)
A22: Laundry | B22: 15 | C22: per unit/mo | D22: 0.03 | E22: =$B$9*$B22*12 | F22: =E22*(1+$D22) | G22: =F22*(1+$D22) | H22: =G22*(1+$D22) | I22: =H22*(1+$D22) | J22: =I22*(1+$D22) | K22: =J22*(1+$D22) | L22: =K22*(1+$D22) | M22: =L22*(1+$D22) | N22: =M22*(1+$D22)
A23: Pet Fees | B23: 30 | C23: per unit/mo | D23: 0.03 | E23: =$B$9*$B23*12 | F23: =E23*(1+$D23) | G23: =F23*(1+$D23) | H23: =G23*(1+$D23) | I23: =H23*(1+$D23) | J23: =I23*(1+$D23) | K23: =J23*(1+$D23) | L23: =K23*(1+$D23) | M23: =L23*(1+$D23) | N23: =M23*(1+$D23)
A24: Application/Admin Fees | B24: 10 | C24: per unit/mo | D24: 0.03 | E24: =$B$9*$B24*12 | F24: =E24*(1+$D24) | G24: =F24*(1+$D24) | H24: =G24*(1+$D24) | I24: =H24*(1+$D24) | J24: =I24*(1+$D24) | K24: =J24*(1+$D24) | L24: =K24*(1+$D24) | M24: =L24*(1+$D24) | N24: =M24*(1+$D24)
A25: Total Other Income | E25: =SUM(E20:E24) | F25: =SUM(F20:F24) | G25: =SUM(G20:G24) | H25: =SUM(H20:H24) | I25: =SUM(I20:I24) | J25: =SUM(J20:J24) | K25: =SUM(K20:K24) | L25: =SUM(L20:L24) | ... N25: =SUM(N20:N24)
A27: EFFECTIVE GROSS INCOME (EGI) | E27: =E17+E25 | F27: =F17+F25 | G27: =G17+G25 | H27: =H17+H25 | I27: =I17+I25 | J27: =J17+J25 | K27: =K17+K25 | L27: =L17+L25 | ... N27: =N17+N25

Sheet 4_Operating Expenses
A1: OPERATING EXPENSES
A3: Expense Category | B3: % of EGI | C3: Growth | D3: Year 1 | E3: Year 2 | F3: Year 3 | G3: Year 4 | H3: Year 5 | I3: Year 6 | J3: Year 7 | K3: Year 8 | L3: Year 9 | M3: Year 10
A4: Effective Gross Income (Ref) | D4: ='3_Unit Mix Revenue'!E27 | E4: ='3_Unit Mix Revenue'!F27 | F4: ='3_Unit Mix Revenue'!G27 | G4: ='3_Unit Mix Revenue'!H27 | H4: ='3_Unit Mix Revenue'!I27 | I4: ='3_Unit Mix Revenue'!J27 | J4: ='3_Unit Mix Revenue'!K27 | K4: ='3_Unit Mix Revenue'!L27 | ... M4: ='3_Unit Mix Revenue'!N27
A5: OPERATING EXPENSES
A6: Payroll | B6: 0.05 | C6: 0.03 | D6: =$D$4*$B6 | E6: =D6*(1+$C6) | F6: =E6*(1+$C6) | G6: =F6*(1+$C6) | H6: =G6*(1+$C6) | I6: =H6*(1+$C6) | J6: =I6*(1+$C6) | K6: =J6*(1+$C6) | L6: =K6*(1+$C6) | M6: =L6*(1+$C6)
A7: Utilities | B7: 0.03 | C7: 0.025 | D7: =$D$4*$B7 | E7: =D7*(1+$C7) | F7: =E7*(1+$C7) | G7: =F7*(1+$C7) | H7: =G7*(1+$C7) | I7: =H7*(1+$C7) | J7: =I7*(1+$C7) | K7: =J7*(1+$C7) | L7: =K7*(1+$C7) | M7: =L7*(1+$C7)
A8: Repairs & Maintenance | B8: 0.04 | C8: 0.03 | D8: =$D$4*$B8 | E8: =D8*(1+$C8) | F8: =E8*(1+$C8) | G8: =F8*(1+$C8) | H8: =G8*(1+$C8) | I8: =H8*(1+$C8) | J8: =I8*(1+$C8) | K8: =J8*(1+$C8) | L8: =K8*(1+$C8) | M8: =L8*(1+$C8)
A9: Property Taxes | B9: 0.06 | C9: 0.02 | D9: =$D$4*$B9 | E9: =D9*(1+$C9) | F9: =E9*(1+$C9) | G9: =F9*(1+$C9) | H9: =G9*(1+$C9) | I9: =H9*(1+$C9) | J9: =I9*(1+$C9) | K9: =J9*(1+$C9) | L9: =K9*(1+$C9) | M9: =L9*(1+$C9)
A10: Insurance | B10: 0.02 | C10: 0.04 | D10: =$D$4*$B10 | E10: =D10*(1+$C10) | F10: =E10*(1+$C10) | G10: =F10*(1+$C10) | H10: =G10*(1+$C10) | I10: =H10*(1+$C10) | J10: =I10*(1+$C10) | K10: =J10*(1+$C10) | L10: =K10*(1+$C10) | M10: =L10*(1+$C10)
A11: Marketing & Leasing | B11: 0.015 | C11: 0.03 | D11: =$D$4*$B11 | E11: =D11*(1+$C11) | F11: =E11*(1+$C11) | G11: =F11*(1+$C11) | H11: =G11*(1+$C11) | I11: =H11*(1+$C11) | J11: =I11*(1+$C11) | K11: =J11*(1+$C11) | L11: =K11*(1+$C11) | M11: =L11*(1+$C11)
A12: General & Administrative | B12: 0.02 | C12: 0.03 | D12: =$D$4*$B12 | E12: =D12*(1+$C12) | F12: =E12*(1+$C12) | G12: =F12*(1+$C12) | H12: =G12*(1+$C12) | I12: =H12*(1+$C12) | J12: =I12*(1+$C12) | K12: =J12*(1+$C12) | L12: =K12*(1+$C12) | M12: =L12*(1+$C12)
A13: Management Fee | B13: 0.03 | C13: 0 | D13: =$D$4*$B13 | E13: =$E$4*$B13 | F13: =$F$4*$B13 | G13: =$G$4*$B13 | H13: =$H$4*$B13 | I13: =$I$4*$B13 | J13: =$J$4*$B13 | K13: =$K$4*$B13 | L13: =$L$4*$B13 | M13: =$M$4*$B13
A14: Replacement Reserves | B14: 0.02 | C14: 0.03 | D14: =$D$4*$B14 | E14: =D14*(1+$C14) | F14: =E14*(1+$C14) | G14: =F14*(1+$C14) | H14: =G14*(1+$C14) | I14: =H14*(1+$C14) | J14: =I14*(1+$C14) | K14: =J14*(1+$C14) | L14: =K14*(1+$C14) | M14: =L14*(1+$C14)
A15: TOTAL OPERATING EXPENSES | D15: =SUM(D6:D14) | E15: =SUM(E6:E14) | F15: =SUM(F6:F14) | G15: =SUM(G6:G14) | H15: =SUM(H6:H14) | I15: =SUM(I6:I14) | J15: =SUM(J6:J14) | K15: =SUM(K6:K14) | ... M15: =SUM(M6:M14)
A16: Operating Expense Ratio | D16: =D15/D4 | E16: =E15/E4 | F16: =F15/F4 | G16: =G15/G4 | H16: =H15/H4 | I16: =I15/I4 | J16: =J15/J4 | K16: =K15/K4 | ... M16: =M15/M4
A18: NET OPERATING INCOME (NOI) | D18: =D4-D15 | E18: =E4-E15 | F18: =F4-F15 | G18: =G4-G15 | H18: =H4-H15 | I18: =I4-I15 | J18: =J4-J15 | K18: =K4-K15 | ... M18: =M4-M15

Sheet 5_Debt Schedule
A1: DEBT SCHEDULE
A3: LOAN INPUTS
A4: Loan-to-Value (LTV) | C4: 0.75
A5: Loan Amount | C5: ='2_Development Budget'!C32*C4
A6: Interest Rate | C6: 0.065
A7: Equity Required | C7: ='2_Development Budget'!C31-C5
A8: Amortization (Years) | C8: 30
A9: Loan Term (Years) | C9: 10
A10: Annual Debt Service | C10: =PMT(C6/12,C8*12,-C5)*12
A12: AMORTIZATION SCHEDULE
A13: Year | B13: Beginning Balance | C13: Annual Payment | D13: Interest | E13: Principal | F13: Ending Balance | G13: DCR
A14: 1 | B14: =$C$5 | C14: =$C$10 | D14: =B14*$C$6 | E14: =C14-D14 | F14: =B14-E14 | G14: ='4_Operating Expenses'!D18/$C$10
A15: 2 | B15: =F14 | C15: =$C$10 | D15: =B15*$C$6 | E15: =C15-D15 | F15: =B15-E15 | G15: ='4_Operating Expenses'!E18/$C$10
A16: 3 | B16: =F15 | C16: =$C$10 | D16: =B16*$C$6 | E16: =C16-D16 | F16: =B16-E16 | G16: ='4_Operating Expenses'!F18/$C$10
A17: 4 | B17: =F16 | C17: =$C$10 | D17: =B17*$C$6 | E17: =C17-D17 | F17: =B17-E17 | G17: ='4_Operating Expenses'!G18/$C$10
A18: 5 | B18: =F17 | C18: =$C$10 | D18: =B18*$C$6 | E18: =C18-D18 | F18: =B18-E18 | G18: ='4_Operating Expenses'!H18/$C$10
A19: 6 | B19: =F18 | C19: =$C$10 | D19: =B19*$C$6 | E19: =C19-D19 | F19: =B19-E19 | G19: ='4_Operating Expenses'!I18/$C$10
A20: 7 | B20: =F19 | C20: =$C$10 | D20: =B20*$C$6 | E20: =C20-D20 | F20: =B20-E20 | G20: ='4_Operating Expenses'!J18/$C$10
A21: 8 | B21: =F20 | C21: =$C$10 | D21: =B21*$C$6 | E21: =C21-D21 | F21: =B21-E21 | G21: ='4_Operating Expenses'!K18/$C$10
A22: 9 | B22: =F21 | C22: =$C$10 | D22: =B22*$C$6 | E22: =C22-D22 | F22: =B22-E22 | G22: ='4_Operating Expenses'!L18/$C$10
A23: 10 | B23: =F22 | C23: =$C$10 | D23: =B23*$C$6 | E23: =C23-D23 | F23: =B23-E23 | G23: ='4_Operating Expenses'!M18/$C$10

Sheet 6_Cash Flow Analysis
A1: CASH FLOW ANALYSIS
A3: Cash Flow Item | B3: Year 1 | C3: Year 2 | D3: Year 3 | E3: Year 4 | F3: Year 5 | G3: Year 6 | H3: Year 7 | I3: Year 8 | J3: Year 9 | K3: Year 10 | L3: Total
A4: OPERATING CASH FLOWS
A5: Net Operating Income | B5: ='4_Operating Expenses'!D18 | C5: ='4_Operating Expenses'!E18 | D5: ='4_Operating Expenses'!F18 | E5: ='4_Operating Expenses'!G18 | F5: ='4_Operating Expenses'!H18 | G5: ='4_Operating Expenses'!I18 | H5: ='4_Operating Expenses'!J18 | I5: ='4_Operating Expenses'!K18 | ... K5: ='4_Operating Expenses'!M18 | L5: =SUM(B5:K5)
A6: Less: Debt Service | B6: =-'5_Debt Schedule'!$C$10 | C6: =-'5_Debt Schedule'!$C$10 | D6: =-'5_Debt Schedule'!$C$10 | E6: =-'5_Debt Schedule'!$C$10 | F6: =-'5_Debt Schedule'!$C$10 | G6: =-'5_Debt Schedule'!$C$10 | H6: =-'5_Debt Schedule'!$C$10 | I6: =-'5_Debt Schedule'!$C$10 | ... K6: =-'5_Debt Schedule'!$C$10 | L6: =SUM(B6:K6)
A7: Free Cash Flow (Pre-Refi) | B7: =B5+B6 | C7: =C5+C6 | D7: =D5+D6 | E7: =E5+E6 | F7: =F5+F6 | G7: =G5+G6 | H7: =H5+H6 | I7: =I5+I6 | ... L7: =L5+L6
A9: REFINANCING (Year 4)
A10: Refi LTV % | B10: 0.75
A11: Refi Cap Rate | B11: 0.055
A12: Stabilized Value at Refi | E12: =E5/$B$11
A13: New Loan Amount (75% LTV) | E13: =E12*$B$10
A14: Less: Existing Loan Balance | E14: =-'5_Debt Schedule'!F17
A15: Refinancing Proceeds | E15: =E13+E14 | L15: =E15
A17: INVESTOR CASH FLOWS
A18: Initial Equity (for reference) | B18: ='5_Debt Schedule'!C7
A19: Less: Asset Mgmt Fee (3%) | B19: =-B7*0.03 | C19: =-C7*0.03 | D19: =-D7*0.03 | E19: =-E7*0.03 | F19: =-F7*0.03 | G19: =-G7*0.03 | H19: =-H7*0.03 | I19: =-I7*0.03 | ... K19: =-K7*0.03 | L19: =SUM(B19:K19)
A20: Net Cash Flow to Investors | B20: =B7+B19 | C20: =C7+C19 | D20: =D7+D19 | E20: =E7+E15+E19 | F20: =F7+F19 | G20: =G7+G19 | H20: =H7+H19 | I20: =I7+I19 | J20: =J7+J19 | K20: =K7+K19 | L20: =SUM(B20:K20)
A22: RETURNS METRICS
A24: Cash-on-Cash Return | B24: =B20/$B$18 | C24: =C20/$B$18 | D24: =D20/$B$18 | E24: =E20/$B$18 | F24: =F20/$B$18 | G24: =G20/$B$18 | H24: =H20/$B$18 | I24: =I20/$B$18 | ... K24: =K20/$B$18
A25: Cumulative Cash Returned | B25: =B20 | C25: =B25+C20 | D25: =C25+D20 | E25: =D25+E20 | F25: =E25+F20 | G25: =F25+G20 | H25: =G25+H20 | I25: =H25+I20 | J25: =I25+J20 | K25: =J25+K20
A26: % of Equity Returned | B26: =B25/$B$18 | C26: =C25/$B$18 | D26: =D25/$B$18 | E26: =E25/$B$18 | F26: =F25/$B$18 | G26: =G25/$B$18 | H26: =H25/$B$18 | I26: =I25/$B$18 | ... K26: =K25/$B$18

Sheet 7_Returns Exit
A1: RETURNS & EXIT ANALYSIS
A3: EXIT ASSUMPTIONS (YEAR 10)
A4: Exit Cap Rate | C4: 0.055
A5: Selling Costs | C5: 0.02
A7: EXIT CALCULATIONS
A8: Projected NOI (Year 10) | C8: ='4_Operating Expenses'!M18
A9: Gross Sale Price (NOI / Cap) | C9: =C8/C4
A10: Less: Selling Costs | C10: =-C9*C5
A11: Net Sale Proceeds | C11: =C9+C10
A12: Less: Remaining Loan Balance | C12: =-'5_Debt Schedule'!F23
A13: Equity Proceeds at Sale | C13: =C11+C12
A15: TOTAL RETURN CALCULATION
A16: Initial Equity Investment | C16: ='5_Debt Schedule'!C7
A17: Total Operating Cash Flow | C17: ='6_Cash Flow Analysis'!L7
A18: Less: Asset Management Fees | C18: ='6_Cash Flow Analysis'!L19
A19: Refinancing Proceeds | C19: ='6_Cash Flow Analysis'!L15
A20: Net Operating Distributions | C20: =C17+C18+C19
A21: Plus: Equity Proceeds at Exit | C21: =C13
A23: TOTAL RETURNS
A24: Gross Proceeds | C24: =C20+C21
A25: Less: Initial Investment | C25: =-C16
A27: Total Return ($) | C27: =C24-C16
A28: Total Return (%) | C28: =C27/C16
A29: Equity Multiple | C29: =C24/C16
A30: Approx. Annualized IRR | C30: =(C29^(1/10))-1
A32: OZ TAX BENEFIT ANALYSIS
A33: Capital Gain Invested | C33: ='1_Summary Dashboard'!B23
A34: Combined Tax Rate | C34: ='1_Summary Dashboard'!B24+'1_Summary Dashboard'!B25
A35: Tax on Original Gain (if paid) | C35: =C33*C34
A37: TRADITIONAL INVESTMENT PATH:
A38: Amount Invested (after tax) | C38: =C33-C35
A39: Return at Same Multiple | C39: =C38*C29
A40: Less: Capital Gains Tax (23.8%) | C40: =-(C39-C38)*0.238
A41: Net After-Tax (Traditional) | C41: =C39+C40
A43: OZ FUND PATH:
A44: Amount Invested (full gain) | C44: =C33
A45: Return at Same Multiple | C45: =C44*C29
A46: Less: Deferred Tax Due (2026) | C46: =-C35
A47: Tax on Appreciation (10yr hold) | C47: 0
A48: Net After-Tax (OZ Fund) | C48: =C45+C46+C47
...
